Workbook

Sheet Calendario 
A1: PROPUESTA DE CALENDARIO — LIGA SANTA LUCÍA 2026–2027
A2: Fecha | B2: Día | C2: Hora | D2: Cancha | E2: Local | F2: Visita
A3: JORNADA 1
A4: Jornada jugada | B4: — | C4: — | D4: — | E4: Valle de Ángeles | F4: C.D. Nacional
A5: Jornada jugada | B5: — | C5: — | D5: — | E5: Guerreros Lenca | F5: Ciclón Azul
A6: Jornada jugada | B6: — | C6: — | D6: — | E6: Francisco Morazán | F6: Independiente
A7: Jornada jugada | B7: — | C7: — | D7: — | E7: Motagua | F7: Golden Boys
A8: Jornada jugada | B8: — | C8: — | D8: — | E8: Integral St. Lucía | F8: Centro América
A9: Jornada jugada | B9: — | C9: — | D9: — | E9: Panamericano | F9: Atlético St. Lucía
A10: Jornada jugada | B10: — | C10: — | D10: — | E10: Osos | F10: Real Tegus
A11: JORNADA 2
A12: Jornada jugada | B12: — | C12: — | D12: — | E12: C.D. Nacional | F12: Independiente
A13: Jornada jugada | B13: — | C13: — | D13: — | E13: Valle de Ángeles | F13: Ciclón Azul
A14: Jornada jugada | B14: — | C14: — | D14: — | E14: Guerreros Lenca | F14: Golden Boys
A15: Jornada jugada | B15: — | C15: — | D15: — | E15: Francisco Morazán | F15: Centro América
A16: Jornada jugada | B16: — | C16: REPROGRAMACIÓN | D16: — | E16: Motagua | F16: Atlético St. Lucía
A17: Jornada jugada | B17: — | C17: REPROGRAMACIÓN | D17: — | E17: Integral St. Lucía | F17: Real Tegus
A18: Jornada jugada | B18: — | C18: REPROGRAMACIÓN | D18: — | E18: Panamericano | F18: Osos
A19: JORNADA 3
A20: 15-oct-2026 | B20: Jueves | C20: 6:30 p. m. | D20: Estrella | E20: Valle de Ángeles | F20: Golden Boys
A21: 15-oct-2026 | B21: Jueves | C21: 8:30 p. m. | D21: Estrella | E21: Integral St. Lucía | F21: Osos
A22: 17-oct-2026 | B22: Sábado | C22: 12:45 p. m. | D22: Estrella | E22: Guerreros Lenca | F22: Francisco Morazán
A23: 17-oct-2026 | B23: Sábado | C23: 2:45 p. m. | D23: Estrella | E23: Real Tegus | F23: Centro América
A24: 17-oct-2026 | B24: Sábado | C24: 12:30 p. m. | D24: Kennedy | E24: Atlético St. Lucía | F24: Ciclón Azul
A25: 17-oct-2026 | B25: Sábado | C25: 2:30 p. m. | D25: Kennedy | E25: Independiente | F25: Motagua
A26: 17-oct-2026 | B26: Sábado | C26: 4:30 p. m. | D26: Kennedy | E26: C.D. Nacional | F26: Panamericano
A27: JORNADA 4
A28: 22-oct-2026 | B28: Jueves | C28: 6:30 p. m. | D28: Estrella | E28: Atlético St. Lucía | F28: C.D. Nacional
A29: 22-oct-2026 | B29: Jueves | C29: 8:30 p. m. | D29: Estrella | E29: Panamericano | F29: Motagua
A30: 24-oct-2026 | B30: Sábado | C30: 12:45 p. m. | D30: Estrella | E30: Integral St. Lucía | F30: Ciclón Azul
A31: 24-oct-2026 | B31: Sábado | C31: 2:45 p. m. | D31: Estrella | E31: Francisco Morazán | F31: Valle de Ángeles
A32: 24-oct-2026 | B32: Sábado | C32: 12:30 p. m. | D32: Kennedy | E32: Guerreros Lenca | F32: Real Tegus
A33: 24-oct-2026 | B33: Sábado | C33: 2:30 p. m. | D33: Kennedy | E33: Centro América | F33: Osos
A34: 24-oct-2026 | B34: Sábado | C34: 4:30 p. m. | D34: Kennedy | E34: Golden Boys | F34: Independiente
A35: JORNADA 5
A36: 29-oct-2026 | B36: Jueves | C36: 6:30 p. m. | D36: Estrella | E36: Ciclón Azul | F36: Golden Boys
A37: 29-oct-2026 | B37: Jueves | C37: 8:30 p. m. | D37: Estrella | E37: Valle de Ángeles | F37: Real Tegus
A38: 31-oct-2026 | B38: Sábado | C38: 12:45 p. m. | D38: Estrella | E38: Atlético St. Lucía | F38: Francisco Morazán
A39: 31-oct-2026 | B39: Sábado | C39: 2:45 p. m. | D39: Estrella | E39: Panamericano | F39: Guerreros Lenca
A40: 31-oct-2026 | B40: Sábado | C40: 12:30 p. m. | D40: Kennedy | E40: Osos | F40: Motagua
...

Sheet Cuadro por sede y horario
A1: PARTIDOS POR EQUIPO, SEDE Y HORARIO — LIGA SANTA LUCÍA 2026–2027 (PROPUESTA CORREGIDA)
A2: Cuenta los partidos de cada equipo (como local o visita) según la propuesta de calendario, jornadas 3 a 13. Se actualiza solo si cambia el calendario.
A4: Equipo | B4: ESTRELLA | G4: KENNEDY | K4: RESUMEN
B5: Jueves | C5: Jueves | D5: Sábado | E5: Sábado | F5: Total Estrella | G5: Sábado | H5: Sábado | I5: Sábado | J5: Total Kennedy | K5: Total jueves | L5: Total sábado | M5: Total jornadas 3–13 | N5: Jornadas 1–2 (sin sede) | O5: Total temporada | P5: Local | Q5: Visita
B6: 6:30 p. m. | C6: 8:30 p. m. | D6: 12:45 p. m. | E6: 2:45 p. m. | G6: 12:30 p. m. | H6: 2:30 p. m. | I6: 4:30 p. m.
A7: Atlético St. Lucía | B7: =COUNTIFS('Calendario '!$D$3:$D$107,"Estrella",'Calendario '!$B$3:$B$107,B$5,'Calendario '!$C$3:$C$107,B$6,'Calendario '!$E$3:$E$107,$A7)+COUNTIFS('Calendario '!$D$3:$D$107,"Estrella",'Calendario '!$B$3:$B$107,B$5,'Calendario '!$C$3:$C$107,B$6,'Calendario '!$F$3:$F$107,$A7) -> 2 | C7: =COUNTIFS('Calendario '!$D$3:$D$107,"Estrella",'Calendario '!$B$3:$B$107,C$5,'Calendario '!$C$3:$C$107,C$6,'Calendario '!$E$3:$E$107,$A7)+COUNTIFS('Calendario '!$D$3:$D$107,"Estrella",'Calendario '!$B$3:$B$107,C$5,'Calendario '!$C$3:$C$107,C$6,'Calendario '!$F$3:$F$107,$A7) -> 2 | D7: =COUNTIFS('Calendario '!$D$3:$D$107,"Estrella",'Calendario '!$B$3:$B$107,D$5,'Calendario '!$C$3:$C$107,D$6,'Calendario '!$E$3:$E$107,$A7)+COUNTIFS('Calendario '!$D$3:$D$107,"Estrella",'Calendario '!$B$3:$B$107,D$5,'Calendario '!$C$3:$C$107,D$6,'Calendario '!$F$3:$F$107,$A7) -> 2 | E7: =COUNTIFS('Calendario '!$D$3:$D$107,"Estrella",'Calendario '!$B$3:$B$107,E$5,'Calendario '!$C$3:$C$107,E$6,'Calendario '!$E$3:$E$107,$A7)+COUNTIFS('Calendario '!$D$3:$D$107,"Estrella",'Calendario '!$B$3:$B$107,E$5,'Calendario '!$C$3:$C$107,E$6,'Calendario '!$F$3:$F$107,$A7) -> 2 | F7: =SUM(B7:E7) -> 8 | G7: =COUNTIFS('Calendario '!$D$3:$D$107,"Kennedy",'Calendario '!$B$3:$B$107,G$5,'Calendario '!$C$3:$C$107,G$6,'Calendario '!$E$3:$E$107,$A7)+COUNTIFS('Calendario '!$D$3:$D$107,"Kennedy",'Calendario '!$B$3:$B$107,G$5,'Calendario '!$C$3:$C$107,G$6,'Calendario '!$F$3:$F$107,$A7) -> 1 | H7: =COUNTIFS('Calendario '!$D$3:$D$107,"Kennedy",'Calendario '!$B$3:$B$107,H$5,'Calendario '!$C$3:$C$107,H$6,'Calendario '!$E$3:$E$107,$A7)+COUNTIFS('Calendario '!$D$3:$D$107,"Kennedy",'Calendario '!$B$3:$B$107,H$5,'Calendario '!$C$3:$C$107,H$6,'Calendario '!$F$3:$F$107,$A7) -> 1 | I7: =COUNTIFS('Calendario '!$D$3:$D$107,"Kennedy",'Calendario '!$B$3:$B$107,I$5,'Calendario '!$C$3:$C$107,I$6,'Calendario '!$E$3:$E$107,$A7)+COUNTIFS('Calendario '!$D$3:$D$107,"Kennedy",'Calendario '!$B$3:$B$107,I$5,'Calendario '!$C$3:$C$107,I$6,'Calendario '!$F$3:$F$107,$A7) -> 1 | J7: =SUM(G7:I7) -> 3 | K7: =SUMIF($B$5:$I$5,"Jueves",B7:I7) -> 4 | L7: =SUMIF($B$5:$I$5,"Sábado",B7:I7) -> 7 | M7: =F7+J7 -> 11 | N7: =COUNTIFS('Calendario '!$A$3:$A$107,"Jornada jugada",'Calendario '!$E$3:$E$107,$A7)+COUNTIFS('Calendario '!$A$3:$A$107,"Jornada jugada",'Calendario '!$F$3:$F$107,$A7) -> 2 | O7: =M7+N7 -> 13 | P7: =COUNTIF('Calendario '!$E$3:$E$107,$A7) -> 7 | Q7: =COUNTIF('Calendario '!$F$3:$F$107,$A7) -> 6
A8: C.D. Nacional | B8: =COUNTIFS('Calendario '!$D$3:$D$107,"Estrella",'Calendario '!$B$3:$B$107,B$5,'Calendario '!$C$3:$C$107,B$6,'Calendario '!$E$3:$E$107,$A8)+COUNTIFS('Calendario '!$D$3:$D$107,"Estrella",'Calendario '!$B$3:$B$107,B$5,'Calendario '!$C$3:$C$107,B$6,'Calendario '!$F$3:$F$107,$A8) -> 2 | C8: =COUNTIFS('Calendario '!$D$3:$D$107,"Estrella",'Calendario '!$B$3:$B$107,C$5,'Calendario '!$C$3:$C$107,C$6,'Calendario '!$E$3:$E$107,$A8)+COUNTIFS('Calendario '!$D$3:$D$107,"Estrella",'Calendario '!$B$3:$B$107,C$5,'Calendario '!$C$3:$C$107,C$6,'Calendario '!$F$3:$F$107,$A8) -> 1 | D8: =COUNTIFS('Calendario '!$D$3:$D$107,"Estrella",'Calendario '!$B$3:$B$107,D$5,'Calendario '!$C$3:$C$107,D$6,'Calendario '!$E$3:$E$107,$A8)+COUNTIFS('Calendario '!$D$3:$D$107,"Estrella",'Calendario '!$B$3:$B$107,D$5,'Calendario '!$C$3:$C$107,D$6,'Calendario '!$F$3:$F$107,$A8) -> 1 | E8: =COUNTIFS('Calendario '!$D$3:$D$107,"Estrella",'Calendario '!$B$3:$B$107,E$5,'Calendario '!$C$3:$C$107,E$6,'Calendario '!$E$3:$E$107,$A8)+COUNTIFS('Calendario '!$D$3:$D$107,"Estrella",'Calendario '!$B$3:$B$107,E$5,'Calendario '!$C$3:$C$107,E$6,'Calendario '!$F$3:$F$107,$A8) -> 2 | F8: =SUM(B8:E8) -> 6 | G8: =COUNTIFS('Calendario '!$D$3:$D$107,"Kennedy",'Calendario '!$B$3:$B$107,G$5,'Calendario '!$C$3:$C$107,G$6,'Calendario '!$E$3:$E$107,$A8)+COUNTIFS('Calendario '!$D$3:$D$107,"Kennedy",'Calendario '!$B$3:$B$107,G$5,'Calendario '!$C$3:$C$107,G$6,'Calendario '!$F$3:$F$107,$A8) -> 1 | H8: =COUNTIFS('Calendario '!$D$3:$D$107,"Kennedy",'Calendario '!$B$3:$B$107,H$5,'Calendario '!$C$3:$C$107,H$6,'Calendario '!$E$3:$E$107,$A8)+COUNTIFS('Calendario '!$D$3:$D$107,"Kennedy",'Calendario '!$B$3:$B$107,H$5,'Calendario '!$C$3:$C$107,H$6,'Calendario '!$F$3:$F$107,$A8) -> 2 | I8: =COUNTIFS('Calendario '!$D$3:$D$107,"Kennedy",'Calendario '!$B$3:$B$107,I$5,'Calendario '!$C$3:$C$107,I$6,'Calendario '!$E$3:$E$107,$A8)+COUNTIFS('Calendario '!$D$3:$D$107,"Kennedy",'Calendario '!$B$3:$B$107,I$5,'Calendario '!$C$3:$C$107,I$6,'Calendario '!$F$3:$F$107,$A8) -> 2 | J8: =SUM(G8:I8) -> 5 | K8: =SUMIF($B$5:$I$5,"Jueves",B8:I8) -> 3 | L8: =SUMIF($B$5:$I$5,"Sábado",B8:I8) -> 8 | M8: =F8+J8 -> 11 | N8: =COUNTIFS('Calendario '!$A$3:$A$107,"Jornada jugada",'Calendario '!$E$3:$E$107,$A8)+COUNTIFS('Calendario '!$A$3:$A$107,"Jornada jugada",'Calendario '!$F$3:$F$107,$A8) -> 2 | O8: =M8+N8 -> 13 | P8: =COUNTIF('Calendario '!$E$3:$E$107,$A8) -> 7 | Q8: =COUNTIF('Calendario '!$F$3:$F$107,$A8) -> 6
A9: Centro América | B9: =COUNTIFS('Calendario '!$D$3:$D$107,"Estrella",'Calendario '!$B$3:$B$107,B$5,'Calendario '!$C$3:$C$107,B$6,'Calendario '!$E$3:$E$107,$A9)+COUNTIFS('Calendario '!$D$3:$D$107,"Estrella",'Calendario '!$B$3:$B$107,B$5,'Calendario '!$C$3:$C$107,B$6,'Calendario '!$F$3:$F$107,$A9) -> 2 | C9: =COUNTIFS('Calendario '!$D$3:$D$107,"Estrella",'Calendario '!$B$3:$B$107,C$5,'Calendario '!$C$3:$C$107,C$6,'Calendario '!$E$3:$E$107,$A9)+COUNTIFS('Calendario '!$D$3:$D$107,"Estrella",'Calendario '!$B$3:$B$107,C$5,'Calendario '!$C$3:$C$107,C$6,'Calendario '!$F$3:$F$107,$A9) -> 1 | D9: =COUNTIFS('Calendario '!$D$3:$D$107,"Estrella",'Calendario '!$B$3:$B$107,D$5,'Calendario '!$C$3:$C$107,D$6,'Calendario '!$E$3:$E$107,$A9)+COUNTIFS('Calendario '!$D$3:$D$107,"Estrella",'Calendario '!$B$3:$B$107,D$5,'Calendario '!$C$3:$C$107,D$6,'Calendario '!$F$3:$F$107,$A9) -> 1 | E9: =COUNTIFS('Calendario '!$D$3:$D$107,"Estrella",'Calendario '!$B$3:$B$107,E$5,'Calendario '!$C$3:$C$107,E$6,'Calendario '!$E$3:$E$107,$A9)+COUNTIFS('Calendario '!$D$3:$D$107,"Estrella",'Calendario '!$B$3:$B$107,E$5,'Calendario '!$C$3:$C$107,E$6,'Calendario '!$F$3:$F$107,$A9) -> 2 | F9: =SUM(B9:E9) -> 6 | G9: =COUNTIFS('Calendario '!$D$3:$D$107,"Kennedy",'Calendario '!$B$3:$B$107,G$5,'Calendario '!$C$3:$C$107,G$6,'Calendario '!$E$3:$E$107,$A9)+COUNTIFS('Calendario '!$D$3:$D$107,"Kennedy",'Calendario '!$B$3:$B$107,G$5,'Calendario '!$C$3:$C$107,G$6,'Calendario '!$F$3:$F$107,$A9) -> 1 | H9: =COUNTIFS('Calendario '!$D$3:$D$107,"Kennedy",'Calendario '!$B$3:$B$107,H$5,'Calendario '!$C$3:$C$107,H$6,'Calendario '!$E$3:$E$107,$A9)+COUNTIFS('Calendario '!$D$3:$D$107,"Kennedy",'Calendario '!$B$3:$B$107,H$5,'Calendario '!$C$3:$C$107,H$6,'Calendario '!$F$3:$F$107,$A9) -> 2 | I9: =COUNTIFS('Calendario '!$D$3:$D$107,"Kennedy",'Calendario '!$B$3:$B$107,I$5,'Calendario '!$C$3:$C$107,I$6,'Calendario '!$E$3:$E$107,$A9)+COUNTIFS('Calendario '!$D$3:$D$107,"Kennedy",'Calendario '!$B$3:$B$107,I$5,'Calendario '!$C$3:$C$107,I$6,'Calendario '!$F$3:$F$107,$A9) -> 2 | J9: =SUM(G9:I9) -> 5 | K9: =SUMIF($B$5:$I$5,"Jueves",B9:I9) -> 3 | L9: =SUMIF($B$5:$I$5,"Sábado",B9:I9) -> 8 | M9: =F9+J9 -> 11 | N9: =COUNTIFS('Calendario '!$A$3:$A$107,"Jornada jugada",'Calendario '!$E$3:$E$107,$A9)+COUNTIFS('Calendario '!$A$3:$A$107,"Jornada jugada",'Calendario '!$F$3:$F$107,$A9) -> 2 | O9: =M9+N9 -> 13 | P9: =COUNTIF('Calendario '!$E$3:$E$107,$A9) -> 6 | Q9: =COUNTIF('Calendario '!$F$3:$F$107,$A9) -> 7
A10: Ciclón Azul | B10: =COUNTIFS('Calendario '!$D$3:$D$107,"Estrella",'Calendario '!$B$3:$B$107,B$5,'Calendario '!$C$3:$C$107,B$6,'Calendario '!$E$3:$E$107,$A10)+COUNTIFS('Calendario '!$D$3:$D$107,"Estrella",'Calendario '!$B$3:$B$107,B$5,'Calendario '!$C$3:$C$107,B$6,'Calendario '!$F$3:$F$107,$A10) -> 1 | C10: =COUNTIFS('Calendario '!$D$3:$D$107,"Estrella",'Calendario '!$B$3:$B$107,C$5,'Calendario '!$C$3:$C$107,C$6,'Calendario '!$E$3:$E$107,$A10)+COUNTIFS('Calendario '!$D$3:$D$107,"Estrella",'Calendario '!$B$3:$B$107,C$5,'Calendario '!$C$3:$C$107,C$6,'Calendario '!$F$3:$F$107,$A10) -> 2 | D10: =COUNTIFS('Calendario '!$D$3:$D$107,"Estrella",'Calendario '!$B$3:$B$107,D$5,'Calendario '!$C$3:$C$107,D$6,'Calendario '!$E$3:$E$107,$A10)+COUNTIFS('Calendario '!$D$3:$D$107,"Estrella",'Calendario '!$B$3:$B$107,D$5,'Calendario '!$C$3:$C$107,D$6,'Calendario '!$F$3:$F$107,$A10) -> 2 | E10: =COUNTIFS('Calendario '!$D$3:$D$107,"Estrella",'Calendario '!$B$3:$B$107,E$5,'Calendario '!$C$3:$C$107,E$6,'Calendario '!$E$3:$E$107,$A10)+COUNTIFS('Calendario '!$D$3:$D$107,"Estrella",'Calendario '!$B$3:$B$107,E$5,'Calendario '!$C$3:$C$107,E$6,'Calendario '!$F$3:$F$107,$A10) -> 1 | F10: =SUM(B10:E10) -> 6 | G10: =COUNTIFS('Calendario '!$D$3:$D$107,"Kennedy",'Calendario '!$B$3:$B$107,G$5,'Calendario '!$C$3:$C$107,G$6,'Calendario '!$E$3:$E$107,$A10)+COUNTIFS('Calendario '!$D$3:$D$107,"Kennedy",'Calendario '!$B$3:$B$107,G$5,'Calendario '!$C$3:$C$107,G$6,'Calendario '!$F$3:$F$107,$A10) -> 2 | H10: =COUNTIFS('Calendario '!$D$3:$D$107,"Kennedy",'Calendario '!$B$3:$B$107,H$5,'Calendario '!$C$3:$C$107,H$6,'Calendario '!$E$3:$E$107,$A10)+COUNTIFS('Calendario '!$D$3:$D$107,"Kennedy",'Calendario '!$B$3:$B$107,H$5,'Calendario '!$C$3:$C$107,H$6,'Calendario '!$F$3:$F$107,$A10) -> 2 | I10: =COUNTIFS('Calendario '!$D$3:$D$107,"Kennedy",'Calendario '!$B$3:$B$107,I$5,'Calendario '!$C$3:$C$107,I$6,'Calendario '!$E$3:$E$107,$A10)+COUNTIFS('Calendario '!$D$3:$D$107,"Kennedy",'Calendario '!$B$3:$B$107,I$5,'Calendario '!$C$3:$C$107,I$6,'Calendario '!$F$3:$F$107,$A10) -> 1 | J10: =SUM(G10:I10) -> 5 | K10: =SUMIF($B$5:$I$5,"Jueves",B10:I10) -> 3 | L10: =SUMIF($B$5:$I$5,"Sábado",B10:I10) -> 8 | M10: =F10+J10 -> 11 | N10: =COUNTIFS('Calendario '!$A$3:$A$107,"Jornada jugada",'Calendario '!$E$3:$E$107,$A10)+COUNTIFS('Calendario '!$A$3:$A$107,"Jornada jugada",'Calendario '!$F$3:$F$107,$A10) -> 2 | O10: =M10+N10 -> 13 | P10: =COUNTIF('Calendario '!$E$3:$E$107,$A10) -> 6 | Q10: =COUNTIF('Calendario '!$F$3:$F$107,$A10) -> 7
A11: Francisco Morazán | B11: =COUNTIFS('Calendario '!$D$3:$D$107,"Estrella",'Calendario '!$B$3:$B$107,B$5,'Calendario '!$C$3:$C$107,B$6,'Calendario '!$E$3:$E$107,$A11)+COUNTIFS('Calendario '!$D$3:$D$107,"Estrella",'Calendario '!$B$3:$B$107,B$5,'Calendario '!$C$3:$C$107,B$6,'Calendario '!$F$3:$F$107,$A11) -> 1 | C11: =COUNTIFS('Calendario '!$D$3:$D$107,"Estrella",'Calendario '!$B$3:$B$107,C$5,'Calendario '!$C$3:$C$107,C$6,'Calendario '!$E$3:$E$107,$A11)+COUNTIFS('Calendario '!$D$3:$D$107,"Estrella",'Calendario '!$B$3:$B$107,C$5,'Calendario '!$C$3:$C$107,C$6,'Calendario '!$F$3:$F$107,$A11) -> 1 | D11: =COUNTIFS('Calendario '!$D$3:$D$107,"Estrella",'Calendario '!$B$3:$B$107,D$5,'Calendario '!$C$3:$C$107,D$6,'Calendario '!$E$3:$E$107,$A11)+COUNTIFS('Calendario '!$D$3:$D$107,"Estrella",'Calendario '!$B$3:$B$107,D$5,'Calendario '!$C$3:$C$107,D$6,'Calendario '!$F$3:$F$107,$A11) -> 2 | E11: =COUNTIFS('Calendario '!$D$3:$D$107,"Estrella",'Calendario '!$B$3:$B$107,E$5,'Calendario '!$C$3:$C$107,E$6,'Calendario '!$E$3:$E$107,$A11)+COUNTIFS('Calendario '!$D$3:$D$107,"Estrella",'Calendario '!$B$3:$B$107,E$5,'Calendario '!$C$3:$C$107,E$6,'Calendario '!$F$3:$F$107,$A11) -> 2 | F11: =SUM(B11:E11) -> 6 | G11: =COUNTIFS('Calendario '!$D$3:$D$107,"Kennedy",'Calendario '!$B$3:$B$107,G$5,'Calendario '!$C$3:$C$107,G$6,'Calendario '!$E$3:$E$107,$A11)+COUNTIFS('Calendario '!$D$3:$D$107,"Kennedy",'Calendario '!$B$3:$B$107,G$5,'Calendario '!$C$3:$C$107,G$6,'Calendario '!$F$3:$F$107,$A11) -> 2 | H11: =COUNTIFS('Calendario '!$D$3:$D$107,"Kennedy",'Calendario '!$B$3:$B$107,H$5,'Calendario '!$C$3:$C$107,H$6,'Calendario '!$E$3:$E$107,$A11)+COUNTIFS('Calendario '!$D$3:$D$107,"Kennedy",'Calendario '!$B$3:$B$107,H$5,'Calendario '!$C$3:$C$107,H$6,'Calendario '!$F$3:$F$107,$A11) -> 1 | I11: =COUNTIFS('Calendario '!$D$3:$D$107,"Kennedy",'Calendario '!$B$3:$B$107,I$5,'Calendario '!$C$3:$C$107,I$6,'Calendario '!$E$3:$E$107,$A11)+COUNTIFS('Calendario '!$D$3:$D$107,"Kennedy",'Calendario '!$B$3:$B$107,I$5,'Calendario '!$C$3:$C$107,I$6,'Calendario '!$F$3:$F$107,$A11) -> 2 | J11: =SUM(G11:I11) -> 5 | K11: =SUMIF($B$5:$I$5,"Jueves",B11:I11) -> 2 | L11: =SUMIF($B$5:$I$5,"Sábado",B11:I11) -> 9 | M11: =F11+J11 -> 11 | N11: =COUNTIFS('Calendario '!$A$3:$A$107,"Jornada jugada",'Calendario '!$E$3:$E$107,$A11)+COUNTIFS('Calendario '!$A$3:$A$107,"Jornada jugada",'Calendario '!$F$3:$F$107,$A11) -> 2 | O11: =M11+N11 -> 13 | P11: =COUNTIF('Calendario '!$E$3:$E$107,$A11) -> 7 | Q11: =COUNTIF('Calendario '!$F$3:$F$107,$A11) -> 6
A12: Golden Boys | B12: =COUNTIFS('Calendario '!$D$3:$D$107,"Estrella",'Calendario '!$B$3:$B$107,B$5,'Calendario '!$C$3:$C$107,B$6,'Calendario '!$E$3:$E$107,$A12)+COUNTIFS('Calendario '!$D$3:$D$107,"Estrella",'Calendario '!$B$3:$B$107,B$5,'Calendario '!$C$3:$C$107,B$6,'Calendario '!$F$3:$F$107,$A12) -> 2 | C12: =COUNTIFS('Calendario '!$D$3:$D$107,"Estrella",'Calendario '!$B$3:$B$107,C$5,'Calendario '!$C$3:$C$107,C$6,'Calendario '!$E$3:$E$107,$A12)+COUNTIFS('Calendario '!$D$3:$D$107,"Estrella",'Calendario '!$B$3:$B$107,C$5,'Calendario '!$C$3:$C$107,C$6,'Calendario '!$F$3:$F$107,$A12) -> 1 | D12: =COUNTIFS('Calendario '!$D$3:$D$107,"Estrella",'Calendario '!$B$3:$B$107,D$5,'Calendario '!$C$3:$C$107,D$6,'Calendario '!$E$3:$E$107,$A12)+COUNTIFS('Calendario '!$D$3:$D$107,"Estrella",'Calendario '!$B$3:$B$107,D$5,'Calendario '!$C$3:$C$107,D$6,'Calendario '!$F$3:$F$107,$A12) -> 2 | E12: =COUNTIFS('Calendario '!$D$3:$D$107,"Estrella",'Calendario '!$B$3:$B$107,E$5,'Calendario '!$C$3:$C$107,E$6,'Calendario '!$E$3:$E$107,$A12)+COUNTIFS('Calendario '!$D$3:$D$107,"Estrella",'Calendario '!$B$3:$B$107,E$5,'Calendario '!$C$3:$C$107,E$6,'Calendario '!$F$3:$F$107,$A12) -> 1 | F12: =SUM(B12:E12) -> 6 | G12: =COUNTIFS('Calendario '!$D$3:$D$107,"Kennedy",'Calendario '!$B$3:$B$107,G$5,'Calendario '!$C$3:$C$107,G$6,'Calendario '!$E$3:$E$107,$A12)+COUNTIFS('Calendario '!$D$3:$D$107,"Kennedy",'Calendario '!$B$3:$B$107,G$5,'Calendario '!$C$3:$C$107,G$6,'Calendario '!$F$3:$F$107,$A12) -> 2 | H12: =COUNTIFS('Calendario '!$D$3:$D$107,"Kennedy",'Calendario '!$B$3:$B$107,H$5,'Calendario '!$C$3:$C$107,H$6,'Calendario '!$E$3:$E$107,$A12)+COUNTIFS('Calendario '!$D$3:$D$107,"Kennedy",'Calendario '!$B$3:$B$107,H$5,'Calendario '!$C$3:$C$107,H$6,'Calendario '!$F$3:$F$107,$A12) -> 1 | I12: =COUNTIFS('Calendario '!$D$3:$D$107,"Kennedy",'Calendario '!$B$3:$B$107,I$5,'Calendario '!$C$3:$C$107,I$6,'Calendario '!$E$3:$E$107,$A12)+COUNTIFS('Calendario '!$D$3:$D$107,"Kennedy",'Calendario '!$B$3:$B$107,I$5,'Calendario '!$C$3:$C$107,I$6,'Calendario '!$F$3:$F$107,$A12) -> 2 | J12: =SUM(G12:I12) -> 5 | K12: =SUMIF($B$5:$I$5,"Jueves",B12:I12) -> 3 | L12: =SUMIF($B$5:$I$5,"Sábado",B12:I12) -> 8 | M12: =F12+J12 -> 11 | N12: =COUNTIFS('Calendario '!$A$3:$A$107,"Jornada jugada",'Calendario '!$E$3:$E$107,$A12)+COUNTIFS('Calendario '!$A$3:$A$107,"Jornada jugada",'Calendario '!$F$3:$F$107,$A12) -> 2 | O12: =M12+N12 -> 13 | P12: =COUNTIF('Calendario '!$E$3:$E$107,$A12) -> 6 | Q12: =COUNTIF('Calendario '!$F$3:$F$107,$A12) -> 7
A13: Guerreros Lenca | B13: =COUNTIFS('Calendario '!$D$3:$D$107,"Estrella",'Calendario '!$B$3:$B$107,B$5,'Calendario '!$C$3:$C$107,B$6,'Calendario '!$E$3:$E$107,$A13)+COUNTIFS('Calendario '!$D$3:$D$107,"Estrella",'Calendario '!$B$3:$B$107,B$5,'Calendario '!$C$3:$C$107,B$6,'Calendario '!$F$3:$F$107,$A13) -> 1 | C13: =COUNTIFS('Calendario '!$D$3:$D$107,"Estrella",'Calendario '!$B$3:$B$107,C$5,'Calendario '!$C$3:$C$107,C$6,'Calendario '!$E$3:$E$107,$A13)+COUNTIFS('Calendario '!$D$3:$D$107,"Estrella",'Calendario '!$B$3:$B$107,C$5,'Calendario '!$C$3:$C$107,C$6,'Calendario '!$F$3:$F$107,$A13) -> 1 | D13: =COUNTIFS('Calendario '!$D$3:$D$107,"Estrella",'Calendario '!$B$3:$B$107,D$5,'Calendario '!$C$3:$C$107,D$6,'Calendario '!$E$3:$E$107,$A13)+COUNTIFS('Calendario '!$D$3:$D$107,"Estrella",'Calendario '!$B$3:$B$107,D$5,'Calendario '!$C$3:$C$107,D$6,'Calendario '!$F$3:$F$107,$A13) -> 2 | E13: =COUNTIFS('Calendario '!$D$3:$D$107,"Estrella",'Calendario '!$B$3:$B$107,E$5,'Calendario '!$C$3:$C$107,E$6,'Calendario '!$E$3:$E$107,$A13)+COUNTIFS('Calendario '!$D$3:$D$107,"Estrella",'Calendario '!$B$3:$B$107,E$5,'Calendario '!$C$3:$C$107,E$6,'Calendario '!$F$3:$F$107,$A13) -> 1 | F13: =SUM(B13:E13) -> 5 | G13: =COUNTIFS('Calendario '!$D$3:$D$107,"Kennedy",'Calendario '!$B$3:$B$107,G$5,'Calendario '!$C$3:$C$107,G$6,'Calendario '!$E$3:$E$107,$A13)+COUNTIFS('Calendario '!$D$3:$D$107,"Kennedy",'Calendario '!$B$3:$B$107,G$5,'Calendario '!$C$3:$C$107,G$6,'Calendario '!$F$3:$F$107,$A13) -> 2 | H13: =COUNTIFS('Calendario '!$D$3:$D$107,"Kennedy",'Calendario '!$B$3:$B$107,H$5,'Calendario '!$C$3:$C$107,H$6,'Calendario '!$E$3:$E$107,$A13)+COUNTIFS('Calendario '!$D$3:$D$107,"Kennedy",'Calendario '!$B$3:$B$107,H$5,'Calendario '!$C$3:$C$107,H$6,'Calendario '!$F$3:$F$107,$A13) -> 2 | I13: =COUNTIFS('Calendario '!$D$3:$D$107,"Kennedy",'Calendario '!$B$3:$B$107,I$5,'Calendario '!$C$3:$C$107,I$6,'Calendario '!$E$3:$E$107,$A13)+COUNTIFS('Calendario '!$D$3:$D$107,"Kennedy",'Calendario '!$B$3:$B$107,I$5,'Calendario '!$C$3:$C$107,I$6,'Calendario '!$F$3:$F$107,$A13) -> 2 | J13: =SUM(G13:I13) -> 6 | K13: =SUMIF($B$5:$I$5,"Jueves",B13:I13) -> 2 | L13: =SUMIF($B$5:$I$5,"Sábado",B13:I13) -> 9 | M13: =F13+J13 -> 11 | N13: =COUNTIFS('Calendario '!$A$3:$A$107,"Jornada jugada",'Calendario '!$E$3:$E$107,$A13)+COUNTIFS('Calendario '!$A$3:$A$107,"Jornada jugada",'Calendario '!$F$3:$F$107,$A13) -> 2 | O13: =M13+N13 -> 13 | P13: =COUNTIF('Calendario '!$E$3:$E$107,$A13) -> 7 | Q13: =COUNTIF('Calendario '!$F$3:$F$107,$A13) -> 6
A14: Independiente | B14: =COUNTIFS('Calendario '!$D$3:$D$107,"Estrella",'Calendario '!$B$3:$B$107,B$5,'Calendario '!$C$3:$C$107,B$6,'Calendario '!$E$3:$E$107,$A14)+COUNTIFS('Calendario '!$D$3:$D$107,"Estrella",'Calendario '!$B$3:$B$107,B$5,'Calendario '!$C$3:$C$107,B$6,'Calendario '!$F$3:$F$107,$A14) -> 1 | C14: =COUNTIFS('Calendario '!$D$3:$D$107,"Estrella",'Calendario '!$B$3:$B$107,C$5,'Calendario '!$C$3:$C$107,C$6,'Calendario '!$E$3:$E$107,$A14)+COUNTIFS('Calendario '!$D$3:$D$107,"Estrella",'Calendario '!$B$3:$B$107,C$5,'Calendario '!$C$3:$C$107,C$6,'Calendario '!$F$3:$F$107,$A14) -> 1 | D14: =COUNTIFS('Calendario '!$D$3:$D$107,"Estrella",'Calendario '!$B$3:$B$107,D$5,'Calendario '!$C$3:$C$107,D$6,'Calendario '!$E$3:$E$107,$A14)+COUNTIFS('Calendario '!$D$3:$D$107,"Estrella",'Calendario '!$B$3:$B$107,D$5,'Calendario '!$C$3:$C$107,D$6,'Calendario '!$F$3:$F$107,$A14) -> 1 | E14: =COUNTIFS('Calendario '!$D$3:$D$107,"Estrella",'Calendario '!$B$3:$B$107,E$5,'Calendario '!$C$3:$C$107,E$6,'Calendario '!$E$3:$E$107,$A14)+COUNTIFS('Calendario '!$D$3:$D$107,"Estrella",'Calendario '!$B$3:$B$107,E$5,'Calendario '!$C$3:$C$107,E$6,'Calendario '!$F$3:$F$107,$A14) -> 2 | F14: =SUM(B14:E14) -> 5 | G14: =COUNTIFS('Calendario '!$D$3:$D$107,"Kennedy",'Calendario '!$B$3:$B$107,G$5,'Calendario '!$C$3:$C$107,G$6,'Calendario '!$E$3:$E$107,$A14)+COUNTIFS('Calendario '!$D$3:$D$107,"Kennedy",'Calendario '!$B$3:$B$107,G$5,'Calendario '!$C$3:$C$107,G$6,'Calendario '!$F$3:$F$107,$A14) -> 2 | H14: =COUNTIFS('Calendario '!$D$3:$D$107,"Kennedy",'Calendario '!$B$3:$B$107,H$5,'Calendario '!$C$3:$C$107,H$6,'Calendario '!$E$3:$E$107,$A14)+COUNTIFS('Calendario '!$D$3:$D$107,"Kennedy",'Calendario '!$B$3:$B$107,H$5,'Calendario '!$C$3:$C$107,H$6,'Calendario '!$F$3:$F$107,$A14) -> 2 | I14: =COUNTIFS('Calendario '!$D$3:$D$107,"Kennedy",'Calendario '!$B$3:$B$107,I$5,'Calendario '!$C$3:$C$107,I$6,'Calendario '!$E$3:$E$107,$A14)+COUNTIFS('Calendario '!$D$3:$D$107,"Kennedy",'Calendario '!$B$3:$B$107,I$5,'Calendario '!$C$3:$C$107,I$6,'Calendario '!$F$3:$F$107,$A14) -> 2 | J14: =SUM(G14:I14) -> 6 | K14: =SUMIF($B$5:$I$5,"Jueves",B14:I14) -> 2 | L14: =SUMIF($B$5:$I$5,"Sábado",B14:I14) -> 9 | M14: =F14+J14 -> 11 | N14: =COUNTIFS('Calendario '!$A$3:$A$107,"Jornada jugada",'Calendario '!$E$3:$E$107,$A14)+COUNTIFS('Calendario '!$A$3:$A$107,"Jornada jugada",'Calendario '!$F$3:$F$107,$A14) -> 2 | O14: =M14+N14 -> 13 | P14: =COUNTIF('Calendario '!$E$3:$E$107,$A14) -> 6 | Q14: =COUNTIF('Calendario '!$F$3:$F$107,$A14) -> 7
A15: Integral St. Lucía | B15: =COUNTIFS('Calendario '!$D$3:$D$107,"Estrella",'Calendario '!$B$3:$B$107,B$5,'Calendario '!$C$3:$C$107,B$6,'Calendario '!$E$3:$E$107,$A15)+COUNTIFS('Calendario '!$D$3:$D$107,"Estrella",'Calendario '!$B$3:$B$107,B$5,'Calendario '!$C$3:$C$107,B$6,'Calendario '!$F$3:$F$107,$A15) -> 2 | C15: =COUNTIFS('Calendario '!$D$3:$D$107,"Estrella",'Calendario '!$B$3:$B$107,C$5,'Calendario '!$C$3:$C$107,C$6,'Calendario '!$E$3:$E$107,$A15)+COUNTIFS('Calendario '!$D$3:$D$107,"Estrella",'Calendario '!$B$3:$B$107,C$5,'Calendario '!$C$3:$C$107,C$6,'Calendario '!$F$3:$F$107,$A15) -> 2 | D15: =COUNTIFS('Calendario '!$D$3:$D$107,"Estrella",'Calendario '!$B$3:$B$107,D$5,'Calendario '!$C$3:$C$107,D$6,'Calendario '!$E$3:$E$107,$A15)+COUNTIFS('Calendario '!$D$3:$D$107,"Estrella",'Calendario '!$B$3:$B$107,D$5,'Calendario '!$C$3:$C$107,D$6,'Calendario '!$F$3:$F$107,$A15) -> 2 | E15: =COUNTIFS('Calendario '!$D$3:$D$107,"Estrella",'Calendario '!$B$3:$B$107,E$5,'Calendario '!$C$3:$C$107,E$6,'Calendario '!$E$3:$E$107,$A15)+COUNTIFS('Calendario '!$D$3:$D$107,"Estrella",'Calendario '!$B$3:$B$107,E$5,'Calendario '!$C$3:$C$107,E$6,'Calendario '!$F$3:$F$107,$A15) -> 2 | F15: =SUM(B15:E15) -> 8 | G15: =COUNTIFS('Calendario '!$D$3:$D$107,"Kennedy",'Calendario '!$B$3:$B$107,G$5,'Calendario '!$C$3:$C$107,G$6,'Calendario '!$E$3:$E$107,$A15)+COUNTIFS('Calendario '!$D$3:$D$107,"Kennedy",'Calendario '!$B$3:$B$107,G$5,'Calendario '!$C$3:$C$107,G$6,'Calendario '!$F$3:$F$107,$A15) -> 1 | H15: =COUNTIFS('Calendario '!$D$3:$D$107,"Kennedy",'Calendario '!$B$3:$B$107,H$5,'Calendario '!$C$3:$C$107,H$6,'Calendario '!$E$3:$E$107,$A15)+COUNTIFS('Calendario '!$D$3:$D$107,"Kennedy",'Calendario '!$B$3:$B$107,H$5,'Calendario '!$C$3:$C$107,H$6,'Calendario '!$F$3:$F$107,$A15) -> 1 | I15: =COUNTIFS('Calendario '!$D$3:$D$107,"Kennedy",'Calendario '!$B$3:$B$107,I$5,'Calendario '!$C$3:$C$107,I$6,'Calendario '!$E$3:$E$107,$A15)+COUNTIFS('Calendario '!$D$3:$D$107,"Kennedy",'Calendario '!$B$3:$B$107,I$5,'Calendario '!$C$3:$C$107,I$6,'Calendario '!$F$3:$F$107,$A15) -> 1 | J15: =SUM(G15:I15) -> 3 | K15: =SUMIF($B$5:$I$5,"Jueves",B15:I15) -> 4 | L15: =SUMIF($B$5:$I$5,"Sábado",B15:I15) -> 7 | M15: =F15+J15 -> 11 | N15: =COUNTIFS('Calendario '!$A$3:$A$107,"Jornada jugada",'Calendario '!$E$3:$E$107,$A15)+COUNTIFS('Calendario '!$A$3:$A$107,"Jornada jugada",'Calendario '!$F$3:$F$107,$A15) -> 2 | O15: =M15+N15 -> 13 | P15: =COUNTIF('Calendario '!$E$3:$E$107,$A15) -> 6 | Q15: =COUNTIF('Calendario '!$F$3:$F$107,$A15) -> 7
A16: Motagua | B16: =COUNTIFS('Calendario '!$D$3:$D$107,"Estrella",'Calendario '!$B$3:$B$107,B$5,'Calendario '!$C$3:$C$107,B$6,'Calendario '!$E$3:$E$107,$A16)+COUNTIFS('Calendario '!$D$3:$D$107,"Estrella",'Calendario '!$B$3:$B$107,B$5,'Calendario '!$C$3:$C$107,B$6,'Calendario '!$F$3:$F$107,$A16) -> 2 | C16: =COUNTIFS('Calendario '!$D$3:$D$107,"Estrella",'Calendario '!$B$3:$B$107,C$5,'Calendario '!$C$3:$C$107,C$6,'Calendario '!$E$3:$E$107,$A16)+COUNTIFS('Calendario '!$D$3:$D$107,"Estrella",'Calendario '!$B$3:$B$107,C$5,'Calendario '!$C$3:$C$107,C$6,'Calendario '!$F$3:$F$107,$A16) -> 2 | D16: =COUNTIFS('Calendario '!$D$3:$D$107,"Estrella",'Calendario '!$B$3:$B$107,D$5,'Calendario '!$C$3:$C$107,D$6,'Calendario '!$E$3:$E$107,$A16)+COUNTIFS('Calendario '!$D$3:$D$107,"Estrella",'Calendario '!$B$3:$B$107,D$5,'Calendario '!$C$3:$C$107,D$6,'Calendario '!$F$3:$F$107,$A16) -> 1 | E16: =COUNTIFS('Calendario '!$D$3:$D$107,"Estrella",'Calendario '!$B$3:$B$107,E$5,'Calendario '!$C$3:$C$107,E$6,'Calendario '!$E$3:$E$107,$A16)+COUNTIFS('Calendario '!$D$3:$D$107,"Estrella",'Calendario '!$B$3:$B$107,E$5,'Calendario '!$C$3:$C$107,E$6,'Calendario '!$F$3:$F$107,$A16) -> 1 | F16: =SUM(B16:E16) -> 6 | G16: =COUNTIFS('Calendario '!$D$3:$D$107,"Kennedy",'Calendario '!$B$3:$B$107,G$5,'Calendario '!$C$3:$C$107,G$6,'Calendario '!$E$3:$E$107,$A16)+COUNTIFS('Calendario '!$D$3:$D$107,"Kennedy",'Calendario '!$B$3:$B$107,G$5,'Calendario '!$C$3:$C$107,G$6,'Calendario '!$F$3:$F$107,$A16) -> 2 | H16: =COUNTIFS('Calendario '!$D$3:$D$107,"Kennedy",'Calendario '!$B$3:$B$107,H$5,'Calendario '!$C$3:$C$107,H$6,'Calendario '!$E$3:$E$107,$A16)+COUNTIFS('Calendario '!$D$3:$D$107,"Kennedy",'Calendario '!$B$3:$B$107,H$5,'Calendario '!$C$3:$C$107,H$6,'Calendario '!$F$3:$F$107,$A16) -> 1 | I16: =COUNTIFS('Calendario '!$D$3:$D$107,"Kennedy",'Calendario '!$B$3:$B$107,I$5,'Calendario '!$C$3:$C$107,I$6,'Calendario '!$E$3:$E$107,$A16)+COUNTIFS('Calendario '!$D$3:$D$107,"Kennedy",'Calendario '!$B$3:$B$107,I$5,'Calendario '!$C$3:$C$107,I$6,'Calendario '!$F$3:$F$107,$A16) -> 2 | J16: =SUM(G16:I16) -> 5 | K16: =SUMIF($B$5:$I$5,"Jueves",B16:I16) -> 4 | L16: =SUMIF($B$5:$I$5,"Sábado",B16:I16) -> 7 | M16: =F16+J16 -> 11 | N16: =COUNTIFS('Calendario '!$A$3:$A$107,"Jornada jugada",'Calendario '!$E$3:$E$107,$A16)+COUNTIFS('Calendario '!$A$3:$A$107,"Jornada jugada",'Calendario '!$F$3:$F$107,$A16) -> 2 | O16: =M16+N16 -> 13 | P16: =COUNTIF('Calendario '!$E$3:$E$107,$A16) -> 7 | Q16: =COUNTIF('Calendario '!$F$3:$F$107,$A16) -> 6
A17: Osos | B17: =COUNTIFS('Calendario '!$D$3:$D$107,"Estrella",'Calendario '!$B$3:$B$107,B$5,'Calendario '!$C$3:$C$107,B$6,'Calendario '!$E$3:$E$107,$A17)+COUNTIFS('Calendario '!$D$3:$D$107,"Estrella",'Calendario '!$B$3:$B$107,B$5,'Calendario '!$C$3:$C$107,B$6,'Calendario '!$F$3:$F$107,$A17) -> 1 | C17: =COUNTIFS('Calendario '!$D$3:$D$107,"Estrella",'Calendario '!$B$3:$B$107,C$5,'Calendario '!$C$3:$C$107,C$6,'Calendario '!$E$3:$E$107,$A17)+COUNTIFS('Calendario '!$D$3:$D$107,"Estrella",'Calendario '!$B$3:$B$107,C$5,'Calendario '!$C$3:$C$107,C$6,'Calendario '!$F$3:$F$107,$A17) -> 2 | D17: =COUNTIFS('Calendario '!$D$3:$D$107,"Estrella",'Calendario '!$B$3:$B$107,D$5,'Calendario '!$C$3:$C$107,D$6,'Calendario '!$E$3:$E$107,$A17)+COUNTIFS('Calendario '!$D$3:$D$107,"Estrella",'Calendario '!$B$3:$B$107,D$5,'Calendario '!$C$3:$C$107,D$6,'Calendario '!$F$3:$F$107,$A17) -> 2 | E17: =COUNTIFS('Calendario '!$D$3:$D$107,"Estrella",'Calendario '!$B$3:$B$107,E$5,'Calendario '!$C$3:$C$107,E$6,'Calendario '!$E$3:$E$107,$A17)+COUNTIFS('Calendario '!$D$3:$D$107,"Estrella",'Calendario '!$B$3:$B$107,E$5,'Calendario '!$C$3:$C$107,E$6,'Calendario '!$F$3:$F$107,$A17) -> 1 | F17: =SUM(B17:E17) -> 6 | G17: =COUNTIFS('Calendario '!$D$3:$D$107,"Kennedy",'Calendario '!$B$3:$B$107,G$5,'Calendario '!$C$3:$C$107,G$6,'Calendario '!$E$3:$E$107,$A17)+COUNTIFS('Calendario '!$D$3:$D$107,"Kennedy",'Calendario '!$B$3:$B$107,G$5,'Calendario '!$C$3:$C$107,G$6,'Calendario '!$F$3:$F$107,$A17) -> 2 | H17: =COUNTIFS('Calendario '!$D$3:$D$107,"Kennedy",'Calendario '!$B$3:$B$107,H$5,'Calendario '!$C$3:$C$107,H$6,'Calendario '!$E$3:$E$107,$A17)+COUNTIFS('Calendario '!$D$3:$D$107,"Kennedy",'Calendario '!$B$3:$B$107,H$5,'Calendario '!$C$3:$C$107,H$6,'Calendario '!$F$3:$F$107,$A17) -> 2 | I17: =COUNTIFS('Calendario '!$D$3:$D$107,"Kennedy",'Calendario '!$B$3:$B$107,I$5,'Calendario '!$C$3:$C$107,I$6,'Calendario '!$E$3:$E$107,$A17)+COUNTIFS('Calendario '!$D$3:$D$107,"Kennedy",'Calendario '!$B$3:$B$107,I$5,'Calendario '!$C$3:$C$107,I$6,'Calendario '!$F$3:$F$107,$A17) -> 1 | J17: =SUM(G17:I17) -> 5 | K17: =SUMIF($B$5:$I$5,"Jueves",B17:I17) -> 3 | L17: =SUMIF($B$5:$I$5,"Sábado",B17:I17) -> 8 | M17: =F17+J17 -> 11 | N17: =COUNTIFS('Calendario '!$A$3:$A$107,"Jornada jugada",'Calendario '!$E$3:$E$107,$A17)+COUNTIFS('Calendario '!$A$3:$A$107,"Jornada jugada",'Calendario '!$F$3:$F$107,$A17) -> 2 | O17: =M17+N17 -> 13 | P17: =COUNTIF('Calendario '!$E$3:$E$107,$A17) -> 6 | Q17: =COUNTIF('Calendario '!$F$3:$F$107,$A17) -> 7
A18: Panamericano | B18: =COUNTIFS('Calendario '!$D$3:$D$107,"Estrella",'Calendario '!$B$3:$B$107,B$5,'Calendario '!$C$3:$C$107,B$6,'Calendario '!$E$3:$E$107,$A18)+COUNTIFS('Calendario '!$D$3:$D$107,"Estrella",'Calendario '!$B$3:$B$107,B$5,'Calendario '!$C$3:$C$107,B$6,'Calendario '!$F$3:$F$107,$A18) -> 2 | C18: =COUNTIFS('Calendario '!$D$3:$D$107,"Estrella",'Calendario '!$B$3:$B$107,C$5,'Calendario '!$C$3:$C$107,C$6,'Calendario '!$E$3:$E$107,$A18)+COUNTIFS('Calendario '!$D$3:$D$107,"Estrella",'Calendario '!$B$3:$B$107,C$5,'Calendario '!$C$3:$C$107,C$6,'Calendario '!$F$3:$F$107,$A18) -> 2 | D18: =COUNTIFS('Calendario '!$D$3:$D$107,"Estrella",'Calendario '!$B$3:$B$107,D$5,'Calendario '!$C$3:$C$107,D$6,'Calendario '!$E$3:$E$107,$A18)+COUNTIFS('Calendario '!$D$3:$D$107,"Estrella",'Calendario '!$B$3:$B$107,D$5,'Calendario '!$C$3:$C$107,D$6,'Calendario '!$F$3:$F$107,$A18) -> 1 | E18: =COUNTIFS('Calendario '!$D$3:$D$107,"Estrella",'Calendario '!$B$3:$B$107,E$5,'Calendario '!$C$3:$C$107,E$6,'Calendario '!$E$3:$E$107,$A18)+COUNTIFS('Calendario '!$D$3:$D$107,"Estrella",'Calendario '!$B$3:$B$107,E$5,'Calendario '!$C$3:$C$107,E$6,'Calendario '!$F$3:$F$107,$A18) -> 1 | F18: =SUM(B18:E18) -> 6 | G18: =COUNTIFS('Calendario '!$D$3:$D$107,"Kennedy",'Calendario '!$B$3:$B$107,G$5,'Calendario '!$C$3:$C$107,G$6,'Calendario '!$E$3:$E$107,$A18)+COUNTIFS('Calendario '!$D$3:$D$107,"Kennedy",'Calendario '!$B$3:$B$107,G$5,'Calendario '!$C$3:$C$107,G$6,'Calendario '!$F$3:$F$107,$A18) -> 1 | H18: =COUNTIFS('Calendario '!$D$3:$D$107,"Kennedy",'Calendario '!$B$3:$B$107,H$5,'Calendario '!$C$3:$C$107,H$6,'Calendario '!$E$3:$E$107,$A18)+COUNTIFS('Calendario '!$D$3:$D$107,"Kennedy",'Calendario '!$B$3:$B$107,H$5,'Calendario '!$C$3:$C$107,H$6,'Calendario '!$F$3:$F$107,$A18) -> 2 | I18: =COUNTIFS('Calendario '!$D$3:$D$107,"Kennedy",'Calendario '!$B$3:$B$107,I$5,'Calendario '!$C$3:$C$107,I$6,'Calendario '!$E$3:$E$107,$A18)+COUNTIFS('Calendario '!$D$3:$D$107,"Kennedy",'Calendario '!$B$3:$B$107,I$5,'Calendario '!$C$3:$C$107,I$6,'Calendario '!$F$3:$F$107,$A18) -> 2 | J18: =SUM(G18:I18) -> 5 | K18: =SUMIF($B$5:$I$5,"Jueves",B18:I18) -> 4 | L18: =SUMIF($B$5:$I$5,"Sábado",B18:I18) -> 7 | M18: =F18+J18 -> 11 | N18: =COUNTIFS('Calendario '!$A$3:$A$107,"Jornada jugada",'Calendario '!$E$3:$E$107,$A18)+COUNTIFS('Calendario '!$A$3:$A$107,"Jornada jugada",'Calendario '!$F$3:$F$107,$A18) -> 2 | O18: =M18+N18 -> 13 | P18: =COUNTIF('Calendario '!$E$3:$E$107,$A18) -> 7 | Q18: =COUNTIF('Calendario '!$F$3:$F$107,$A18) -> 6
... A20: Valle de Ángeles | B20: =COUNTIFS('Calendario '!$D$3:$D$107,"Estrella",'Calendario '!$B$3:$B$107,B$5,'Calendario '!$C$3:$C$107,B$6,'Calendario '!$E$3:$E$107,$A20)+COUNTIFS('Calendario '!$D$3:$D$107,"Estrella",'Calendario '!$B$3:$B$107,B$5,'Calendario '!$C$3:$C$107,B$6,'Calendario '!$F$3:$F$107,$A20) -> 2 | C20: =COUNTIFS('Calendario '!$D$3:$D$107,"Estrella",'Calendario '!$B$3:$B$107,C$5,'Calendario '!$C$3:$C$107,C$6,'Calendario '!$E$3:$E$107,$A20)+COUNTIFS('Calendario '!$D$3:$D$107,"Estrella",'Calendario '!$B$3:$B$107,C$5,'Calendario '!$C$3:$C$107,C$6,'Calendario '!$F$3:$F$107,$A20) -> 2 | D20: =COUNTIFS('Calendario '!$D$3:$D$107,"Estrella",'Calendario '!$B$3:$B$107,D$5,'Calendario '!$C$3:$C$107,D$6,'Calendario '!$E$3:$E$107,$A20)+COUNTIFS('Calendario '!$D$3:$D$107,"Estrella",'Calendario '!$B$3:$B$107,D$5,'Calendario '!$C$3:$C$107,D$6,'Calendario '!$F$3:$F$107,$A20) -> 2 | E20: =COUNTIFS('Calendario '!$D$3:$D$107,"Estrella",'Calendario '!$B$3:$B$107,E$5,'Calendario '!$C$3:$C$107,E$6,'Calendario '!$E$3:$E$107,$A20)+COUNTIFS('Calendario '!$D$3:$D$107,"Estrella",'Calendario '!$B$3:$B$107,E$5,'Calendario '!$C$3:$C$107,E$6,'Calendario '!$F$3:$F$107,$A20) -> 2 | F20: =SUM(B20:E20) -> 8 | G20: =COUNTIFS('Calendario '!$D$3:$D$107,"Kennedy",'Calendario '!$B$3:$B$107,G$5,'Calendario '!$C$3:$C$107,G$6,'Calendario '!$E$3:$E$107,$A20)+COUNTIFS('Calendario '!$D$3:$D$107,"Kennedy",'Calendario '!$B$3:$B$107,G$5,'Calendario '!$C$3:$C$107,G$6,'Calendario '!$F$3:$F$107,$A20) -> 1 | H20: =COUNTIFS('Calendario '!$D$3:$D$107,"Kennedy",'Calendario '!$B$3:$B$107,H$5,'Calendario '!$C$3:$C$107,H$6,'Calendario '!$E$3:$E$107,$A20)+COUNTIFS('Calendario '!$D$3:$D$107,"Kennedy",'Calendario '!$B$3:$B$107,H$5,'Calendario '!$C$3:$C$107,H$6,'Calendario '!$F$3:$F$107,$A20) -> 1 | I20: =COUNTIFS('Calendario '!$D$3:$D$107,"Kennedy",'Calendario '!$B$3:$B$107,I$5,'Calendario '!$C$3:$C$107,I$6,'Calendario '!$E$3:$E$107,$A20)+COUNTIFS('Calendario '!$D$3:$D$107,"Kennedy",'Calendario '!$B$3:$B$107,I$5,'Calendario '!$C$3:$C$107,I$6,'Calendario '!$F$3:$F$107,$A20) -> 1 | J20: =SUM(G20:I20) -> 3 | K20: =SUMIF($B$5:$I$5,"Jueves",B20:I20) -> 4 | L20: =SUMIF($B$5:$I$5,"Sábado",B20:I20) -> 7 | M20: =F20+J20 -> 11 | N20: =COUNTIFS('Calendario '!$A$3:$A$107,"Jornada jugada",'Calendario '!$E$3:$E$107,$A20)+COUNTIFS('Calendario '!$A$3:$A$107,"Jornada jugada",'Calendario '!$F$3:$F$107,$A20) -> 2 | O20: =M20+N20 -> 13 | P20: =COUNTIF('Calendario '!$E$3:$E$107,$A20) -> 7 | Q20: =COUNTIF('Calendario '!$F$3:$F$107,$A20) -> 6
A21: TOTAL DE PARTIDOS | B21: =SUM(B7:B20)/2 -> 11 | C21: =SUM(C7:C20)/2 -> 11 | D21: =SUM(D7:D20)/2 -> 11 | E21: =SUM(E7:E20)/2 -> 11 | F21: =SUM(F7:F20)/2 -> 44 | G21: =SUM(G7:G20)/2 -> 11 | H21: =SUM(H7:H20)/2 -> 11 | I21: =SUM(I7:I20)/2 -> 11 | ... O21: =SUM(O7:O20)/2 -> 91 | P21: =SUM(P7:P20) -> 91 | Q21: =SUM(Q7:Q20) -> 91
A23: Notas:
A24: Cada partido cuenta para los dos equipos; por eso la fila TOTAL divide entre 2 y muestra partidos reales por franja.
A25: Las jornadas 1 y 2 no tienen sede ni horario en el calendario (jugadas o en reprogramación); se muestran aparte.
A26: Jueves solo se juega en Estrella; Kennedy solo los sábados.
